INFO    : Since no target was supplied, we will use "web".

INFO    : Found entry no longer exists 88394
INFO    : Now preparing local server to preview your project directory `/Users/pstaab/Documents/courses/math4400/linear-optimization-book`.
INFO    :   (Reminder: use `pretext deploy` to deploy your built project to a public
INFO    :   GitHub Pages site that can be shared with readers who cannot access your
INFO    :   personal computer.)
INFO    : 
INFO    : starting server ...
INFO    : setting up ...
INFO    : values set...
INFO    : adding server entry
INFO    : There are 10 or more servers on file. Cleaning up ...
INFO    : Found entry no longer exists 84815
INFO    : Terminating 84815
INFO    : Terminate failed for 84815.
ERROR   : process PID not found (pid=84815)
Traceback (most recent call last):
  File "/Users/pstaab/.local/pipx/venvs/pretext/lib/python3.13/site-packages/pretext/server.py", line 76, in terminate
    psutil.Process(self.pid).terminate()
    ~~~~~~~~~~~~~~^^^^^^^^^^
  File "/Users/pstaab/.local/pipx/venvs/pretext/lib/python3.13/site-packages/psutil/__init__.py", line 317, in __init__
    self._init(pid)
    ~~~~~~~~~~^^^^^
  File "/Users/pstaab/.local/pipx/venvs/pretext/lib/python3.13/site-packages/psutil/__init__.py", line 363, in _init
    raise NoSuchProcess(pid, msg=msg) from None
psutil.NoSuchProcess: process PID not found (pid=84815)
INFO    : Found entry no longer exists 88394
INFO    : Terminating 88394
INFO    : Terminate failed for 88394.
ERROR   : process PID not found (pid=88394)
Traceback (most recent call last):
  File "/Users/pstaab/.local/pipx/venvs/pretext/lib/python3.13/site-packages/pretext/server.py", line 76, in terminate
    psutil.Process(self.pid).terminate()
    ~~~~~~~~~~~~~~^^^^^^^^^^
  File "/Users/pstaab/.local/pipx/venvs/pretext/lib/python3.13/site-packages/psutil/__init__.py", line 317, in __init__
    self._init(pid)
    ~~~~~~~~~~^^^^^
  File "/Users/pstaab/.local/pipx/venvs/pretext/lib/python3.13/site-packages/psutil/__init__.py", line 363, in _init
    raise NoSuchProcess(pid, msg=msg) from None
psutil.NoSuchProcess: process PID not found (pid=88394)
INFO    : Found entry no longer exists 89946
INFO    : Terminating 89946
INFO    : Terminate failed for 89946.
ERROR   : process PID not found (pid=89946)
Traceback (most recent call last):
  File "/Users/pstaab/.local/pipx/venvs/pretext/lib/python3.13/site-packages/pretext/server.py", line 76, in terminate
    psutil.Process(self.pid).terminate()
    ~~~~~~~~~~~~~~^^^^^^^^^^
  File "/Users/pstaab/.local/pipx/venvs/pretext/lib/python3.13/site-packages/psutil/__init__.py", line 317, in __init__
    self._init(pid)
    ~~~~~~~~~~^^^^^
  File "/Users/pstaab/.local/pipx/venvs/pretext/lib/python3.13/site-packages/psutil/__init__.py", line 363, in _init
    raise NoSuchProcess(pid, msg=msg) from None
psutil.NoSuchProcess: process PID not found (pid=89946)
INFO    : Found entry no longer exists 36407
INFO    : Terminating 36407
INFO    : Terminate failed for 36407.
ERROR   : process PID not found (pid=36407)
Traceback (most recent call last):
  File "/Users/pstaab/.local/pipx/venvs/pretext/lib/python3.13/site-packages/pretext/server.py", line 76, in terminate
    psutil.Process(self.pid).terminate()
    ~~~~~~~~~~~~~~^^^^^^^^^^
  File "/Users/pstaab/.local/pipx/venvs/pretext/lib/python3.13/site-packages/psutil/__init__.py", line 317, in __init__
    self._init(pid)
    ~~~~~~~~~~^^^^^
  File "/Users/pstaab/.local/pipx/venvs/pretext/lib/python3.13/site-packages/psutil/__init__.py", line 363, in _init
    raise NoSuchProcess(pid, msg=msg) from None
psutil.NoSuchProcess: process PID not found (pid=36407)
INFO    : Found entry no longer exists 37910
INFO    : Terminating 37910
INFO    : Terminate failed for 37910.
ERROR   : process PID not found (pid=37910)
Traceback (most recent call last):
  File "/Users/pstaab/.local/pipx/venvs/pretext/lib/python3.13/site-packages/pretext/server.py", line 76, in terminate
    psutil.Process(self.pid).terminate()
    ~~~~~~~~~~~~~~^^^^^^^^^^
  File "/Users/pstaab/.local/pipx/venvs/pretext/lib/python3.13/site-packages/psutil/__init__.py", line 317, in __init__
    self._init(pid)
    ~~~~~~~~~~^^^^^
  File "/Users/pstaab/.local/pipx/venvs/pretext/lib/python3.13/site-packages/psutil/__init__.py", line 363, in _init
    raise NoSuchProcess(pid, msg=msg) from None
psutil.NoSuchProcess: process PID not found (pid=37910)
INFO    : Found entry no longer exists 61182
INFO    : Terminating 61182
INFO    : Terminate failed for 61182.
ERROR   : process PID not found (pid=61182)
Traceback (most recent call last):
  File "/Users/pstaab/.local/pipx/venvs/pretext/lib/python3.13/site-packages/pretext/server.py", line 76, in terminate
    psutil.Process(self.pid).terminate()
    ~~~~~~~~~~~~~~^^^^^^^^^^
  File "/Users/pstaab/.local/pipx/venvs/pretext/lib/python3.13/site-packages/psutil/__init__.py", line 317, in __init__
    self._init(pid)
    ~~~~~~~~~~^^^^^
  File "/Users/pstaab/.local/pipx/venvs/pretext/lib/python3.13/site-packages/psutil/__init__.py", line 363, in _init
    raise NoSuchProcess(pid, msg=msg) from None
psutil.NoSuchProcess: process PID not found (pid=61182)
INFO    : Found entry no longer exists 3234
INFO    : Terminating 3234
INFO    : Terminate failed for 3234.
ERROR   : process PID not found (pid=3234)
Traceback (most recent call last):
  File "/Users/pstaab/.local/pipx/venvs/pretext/lib/python3.13/site-packages/pretext/server.py", line 76, in terminate
    psutil.Process(self.pid).terminate()
    ~~~~~~~~~~~~~~^^^^^^^^^^
  File "/Users/pstaab/.local/pipx/venvs/pretext/lib/python3.13/site-packages/psutil/__init__.py", line 317, in __init__
    self._init(pid)
    ~~~~~~~~~~^^^^^
  File "/Users/pstaab/.local/pipx/venvs/pretext/lib/python3.13/site-packages/psutil/__init__.py", line 363, in _init
    raise NoSuchProcess(pid, msg=msg) from None
psutil.NoSuchProcess: process PID not found (pid=3234)
INFO    : Found entry no longer exists 44437
INFO    : Terminating 44437
INFO    : Terminate failed for 44437.
ERROR   : process PID not found (pid=44437)
Traceback (most recent call last):
  File "/Users/pstaab/.local/pipx/venvs/pretext/lib/python3.13/site-packages/pretext/server.py", line 76, in terminate
    psutil.Process(self.pid).terminate()
    ~~~~~~~~~~~~~~^^^^^^^^^^
  File "/Users/pstaab/.local/pipx/venvs/pretext/lib/python3.13/site-packages/psutil/__init__.py", line 317, in __init__
    self._init(pid)
    ~~~~~~~~~~^^^^^
  File "/Users/pstaab/.local/pipx/venvs/pretext/lib/python3.13/site-packages/psutil/__init__.py", line 363, in _init
    raise NoSuchProcess(pid, msg=msg) from None
psutil.NoSuchProcess: process PID not found (pid=44437)
INFO    : Found entry no longer exists 25842
INFO    : Terminating 25842
INFO    : Terminate failed for 25842.
ERROR   : process PID not found (pid=25842)
Traceback (most recent call last):
  File "/Users/pstaab/.local/pipx/venvs/pretext/lib/python3.13/site-packages/pretext/server.py", line 76, in terminate
    psutil.Process(self.pid).terminate()
    ~~~~~~~~~~~~~~^^^^^^^^^^
  File "/Users/pstaab/.local/pipx/venvs/pretext/lib/python3.13/site-packages/psutil/__init__.py", line 317, in __init__
    self._init(pid)
    ~~~~~~~~~~^^^^^
  File "/Users/pstaab/.local/pipx/venvs/pretext/lib/python3.13/site-packages/psutil/__init__.py", line 363, in _init
    raise NoSuchProcess(pid, msg=msg) from None
psutil.NoSuchProcess: process PID not found (pid=25842)
ERROR   : View encountered an error.  Please report this: process 93888 with laddr 
INFO    : Found server at localhost:8128
INFO    : Added server entry 7ffeefe9fa 93888 8128 localhost

INFO    : Starting the server
INFO    : Server will soon be available at http://localhost:8128
INFO    : The target `web` will be available at http://localhost:8128/output/web
